{
  try {
    internalCleanup();
  }
 catch (  Exception e) {
    log.error("Caught exception in remove",e);
  }
}
